Workbook

Sheet DATA AWAL NASABAH
A1: TANGGAL ANALISA | B1: 45986
A2: NAMA DEBITUR | B2: DYAH RETNO SULISTYOWATI | C2: TGL LAHIR | E2: USIA
A3: TTL | B3: WONOSOBO, 19-04-1978 | C3: =DATEVALUE(RIGHT(B3,LEN(B3)-SEARCH(",",B3)-1)) -> 28599 | D3: =DATEDIF(C3,B1,"Y")&" TAHUN, "&DATEDIF(C3,B1,"YM")&" BULAN" -> 47 TAHUN, 7 BULAN | E3: =DATEDIF(C3,B1,"Y") -> 47 | F3: Tahun
A4: PEKERJAAN | B4: PNS | E4: =DATEDIF(C3,B1,"YM") -> 7 | F4: Bulan
A5: ALAMAT PEKERJAAN | B5: =B9 -> JARAKSARI WONOSOBO | E5: =DATEDIF(C3,B1,"MD") -> 6 | F5: Hari
A6: SUAMI/ISTRI | B6: AFIF NURHIDAYAT | C6: TGL LAHIR | E6: USIA
A7: TTL | B7: WONOSOBO, 25-11-1970 | C7: =DATEVALUE(RIGHT(B7,LEN(B7)-SEARCH(",",B7)-1)) -> 25897 | D7: =DATEDIF(C7,B1,"Y")&" TAHUN, "&DATEDIF(C7,B1,"YM")&" BULAN" -> 55 TAHUN, 0 BULAN | E7: =DATEDIF(C7,B1,"Y") -> 55 | F7: Tahun
A8: PEKERJAAN | B8: BUPATI | E8: =DATEDIF(C7,B1,"YM") -> 0 | F8: Bulan
A9: ALAMAT PEKERJAAN | B9: =""&B12&" "&B13 -> JARAKSARI WONOSOBO | E9: =DATEDIF(C7,B1,"MD") -> 0 | F9: Hari
A10: ALAMAT SESUAI KTP | B10: =""&B11&" "&D11&" "&B12&" "&B13 -> TOSARI REJO 001/006 JARAKSARI WONOSOBO
A11: DUKUH | B11: TOSARI REJO | C11: RT / RW | D11: 001/006 | H11: =""&B11&" "&D11&" "&B12&" "&B13&" "&B14 -> TOSARI REJO 001/006 JARAKSARI WONOSOBO WONOSOBO
A12: DESA | B12: JARAKSARI
A13: KECAMATAN | B13: WONOSOBO
A14: KOTA/KABUPATEN | B14: WONOSOBO
A15: NO HP | B15: 0811261088
A16: NO KTP | B16: 3307095904780003
A17: JML TANGGUNGAN | B17: 3 ORANG
A18: PLAFON | B18: 2000000000
A19: JANGKA WAKTU | B19: 12
A20: BUNGA | B20: 0.015 | D20: =-PMT(B$20/12,$B$19,B18) -> 1.6802393e+08
A21: ALAMAT RUMAH | B21: =B10 -> TOSARI REJO 001/006 JARAKSARI WONOSOBO
A22: NAMA IBU KANDUNG | B22: SRI MURTINI
A23: NAMA INSTANSI/PERUSAHAAN | B23: ALFAMART KALIBEBER MANGGISAN DAN ROJOIMO
A24: ALAMAT INSTANSI/PERUSAHAAN | B24: MUDAL WONOSOBO
A25: NO. TELP KANTOR
A26: DEPARTEMEN/BAGIAN | B26: PERDAGANGAN
A27: JABATAN | B27: PEMILIK
A28: LAMA USAHA | B28: LEBIH DARI 5 TAHUN
A29: TUJUAN PINJAMAN | B29: INVESTASI PEMBELIAN TANAH
A30: ANALIS | B30: ADRIAN WAHYU P
A31: PINJAMAN KE | B31: 10

Sheet ANALISIS
B2: KONDISI KEUANGAN DEBITUR
B4: DATA NASABAH
B5: Nama Debitur | C5: : | D5: ='DATA AWAL NASABAH'!B2 -> DYAH RETNO SULISTYOWATI | F5: Plafon | G5: : | H5: ='DATA AWAL NASABAH'!B18 -> 2000000000
B6: Pekerjaan | C6: : | D6: ='DATA AWAL NASABAH'!B4 -> PNS | F6: Jangka Waktu | G6: : | H6: ='DATA AWAL NASABAH'!B19 -> 12
B7: Alamat tempat kerja | C7: : | D7: ='DATA AWAL NASABAH'!B5 -> JARAKSARI WONOSOBO | F7: Tujuan Penggunaan | G7: : | H7: ='DATA AWAL NASABAH'!B29 -> INVESTASI PEMBELIAN TANAH
B8: NO HP | C8: : | D8: ='DATA AWAL NASABAH'!B15 -> 0811261088 | F8: Bunga | G8: : | H8: ='DATA AWAL NASABAH'!B20 -> 0.015
B9: Jumlah Tanggungan | C9: : | D9: ='DATA AWAL NASABAH'!B17 -> 3 ORANG | F9: Nilai Jaminan | G9: : | H9: ='KOMITE TEMPO'!D11 -> 2755400000
B10: Alamat Sekarang | C10: : | D10: ='DATA AWAL NASABAH'!B21 -> TOSARI REJO 001/006 JARAKSARI WONOSOBO | F10: Nilai Taksasi | G10: : | H10: ='KOMITE TEMPO'!D12 -> 2066550000
B13: INFORMASI KARAKTER DEBITUR | F13: DATA SUAMI/ISTRI NASABAH
B14: Dilingkungan Tinggal | C14: : | D14: DIKENAL | F14: Nama Istri/Suami | G14: : | H14: ='DATA AWAL NASABAH'!B6 -> AFIF NURHIDAYAT
B15: Dilingkungan Kerja | C15: : | D15: DIKENAL | F15: Pekerjaan Istri/Suami | G15: : | H15: ='DATA AWAL NASABAH'!B8 -> BUPATI
B16: Gaya Hidup | C16: : | D16: SEDERHANA | F16: Alamat tempat kerja | G16: : | H16: ='DATA AWAL NASABAH'!B9 -> JARAKSARI WONOSOBO
B17: Indikasi Karakter | C17: : | D17: BAIK | F17: NO HP | G17: : | H17: ='DATA AWAL NASABAH'!B15 -> 0811261088
B19: KETERANGAN TEMPAT USAHA
B20: Nama Perusahaan | C20: : | D20: ='DATA AWAL NASABAH'!B23 -> ALFAMART KALIBEBER MANGGISAN DAN ROJOIMO | F20: Telp/fax | G20: : | H20: -
B21: Bidang Usaha | C21: : | D21: ='DATA AWAL NASABAH'!B26 -> PERDAGANGAN | F21: Lama Usaha | G21: : | H21: ='DATA AWAL NASABAH'!B28 -> LEBIH DARI 5 TAHUN
B22: Alamat Usaha | C22: : | D22: ='DATA AWAL NASABAH'!B24 -> MUDAL WONOSOBO | F22: Status Usaha | G22: : | H22: MILIK SENDIRI
B25: DATA KEUANGAN DEBITUR
B26: PENDAPATAN USAHA | F26: PENGELUARAN
B27: =NERACA!J37 -> Omset Penjualan / Bulan | C27: : | D27: =NERACA!AA37 -> 88229450 | F27: =NERACA!J45 -> Rumah Tangga | G27: : | H27: =NERACA!P45 -> 5000000
C28: : | F28: =NERACA!J46 -> Listrik, Air, Telepon | G28: : | H28: =NERACA!P46 -> 1000000
C29: : | F29: =NERACA!#REF! -> #REF! | G29: : | H29: =NERACA!#REF! -> #REF!
C30: : | F30: =NERACA!J50 -> Angsuran cimb niaga | G30: : | H30: =NERACA!P50 -> 70000
C31: : | F31: =NERACA!J51 -> Sosial & Lain - lain | G31: : | H31: =NERACA!P51 -> 2000000
B32: PENDAPATAN BERSIH USAHA | C32: : | D32: =NERACA!AA38 -> 88229450 | G32: :
B33: Pendapatan Lainya | C33: : | G33: :
B34: Pendapatan Pasangan | C34: : | G34: :
B35: TOTAL PENDAPATAN | C35: : | D35: =D32+D33+D34 -> 88229450 | F35: TOTAL PENGELUARAN | G35: : | H35: =SUM(H27:H34) -> #REF!
B37: KESIMPULAN AKHIR | F37: PERHITUNGAN SETELAH DIBERI KREDIT
B38: TOTAL PENDAPATAN | C38: : | D38: =D35 -> 88229450 | F38: PENDAPATAN | G38: : | H38: =D35 -> 88229450
B39: =F35 -> TOTAL PENGELUARAN | C39: : | D39: =H35 -> #REF! | F39: PENGELUARAN | G39: : | H39: =NERACA!P71 -> 77338584
B40: PENDAPATAN BERSIH | C40: : | D40: =D38-D39 -> #REF! | F40: SISA BERSIH | G40: : | H40: =H38-H39 -> 10890866
B41: PENDAPATAN SAAT PENURUNAN PLAFON | C41: : | D41: =NERACA!AA56 -> 40890866
B42: REPAYMENT CAPACITY | C42: : | D42: =D41*90% -> 36801779 | G42: :
D49: FOTO | F49: FOTO

Sheet KOMITE TEMPO MENURUN
B2: NAMA | C2: : | D2: ='DATA AWAL NASABAH'!B2 -> DYAH RETNO SULISTYOWATI
B3: ALAMAT | C3: : | D3: ='DATA AWAL NASABAH'!B10 -> TOSARI REJO 001/006 JARAKSARI WONOSOBO
B4: Jenis pekerjaan | C4: : | D4: ='DATA AWAL NASABAH'!B4 -> PNS
B6: KEPUTUSAN KOMITE KREDIT
B9: DIUSULKAN DAN MENYETUJUI | F9: CATATAN:
B10: Tanggal | C10: : | D10: ='DATA AWAL NASABAH'!B1 -> 45986 | F10: 1. | G10: NASABAH BEKARAKTER BAIK | I10: PENYEDIA DATA
B11: Jaminan | C11: : | D11: ='KOMITE TEMPO'!D9 -> SHM/NO.01798 & SHM/NO.00817 | F11: 2. | G11: USAHA DEBITUR LANCAR
B12: NJOP | C12: : | D12: ='KOMITE TEMPO'!D10 -> 62167000 | F12: 3. | G12: PINJAMAN YANG KE | H12: =D15 -> 10
B13: Nilai Wajar Jaminan | C13: : | D13: ='KOMITE TEMPO'!D11 -> 2755400000 | F13: 4. | G13: JAMINAN MENCOVER
B14: Nilai Taksasi Bank | C14: : | D14: ='KOMITE TEMPO'!D12 -> 2066550000
B15: Pengambilan ke | C15: : | D15: ='DATA AWAL NASABAH'!B31 -> 10
B16: Tujuan penggunaan | C16: : | D16: ='DATA AWAL NASABAH'!B29 -> INVESTASI PEMBELIAN TANAH
B17: Plafon | C17: : | D17: ='DATA AWAL NASABAH'!B18 -> 2000000000
B18: Jangka Waktu | C18: : | D18: ='DATA AWAL NASABAH'!B19 -> 12 | E18: 0
B19: Sistem angsuran | C19: : | D19: TEMPO MENURUN | I19: ='DATA AWAL NASABAH'!B30 -> ADRIAN WAHYU P
B20: Suku Bunga | C20: : | D20: 1.5 % X POKOK BULAN SEBELUMNYA | I20: ANALIS
B21: Maksimal Angsuran | C21: : | D21: =D17*1.5% -> 30000000
B24: OPINI
I25: MENYETUJUI
I30: NUROHMAN
I31: Kabag Analis
B32: OPINI
I33: MENYETUJUI
I38: RAAFI PURNA AJI
I39: Kabag Kredit
B40: CATATAN:
I41: MENYETUJUI
I46: RIFQY DEWANGGA, S.H
I47: Kadiv Kredit
B48: KEPUTUSAN | C48: : | D48: DISETUJUI / DITOLAK / DISETUJUI TIDAK SESUAI PERMOHONAN
B49: Tanggal | C49: :
B50: Jaminan | C50: :
B51: NJOP | C51: :
B52: Nilai Jaminan | C52: :
B53: Nilai Taksasi Bank | C53: :
B54: Pengambilan ke | C54: :
B55: Tujuan penggunaan | C55: :
B56: Plafon | C56: :
B57: Jangka Waktu | C57: :
B58: Sistem angsuran | C58: :
...

Sheet KOMITE TEMPO
B2: NAMA | C2: : | D2: ='DATA AWAL NASABAH'!B2 -> DYAH RETNO SULISTYOWATI
B3: ALAMAT | C3: : | D3: ='DATA AWAL NASABAH'!B10 -> TOSARI REJO 001/006 JARAKSARI WONOSOBO
B4: Jenis pekerjaan | C4: : | D4: ='DATA AWAL NASABAH'!B4 -> PNS
B6: KEPUTUSAN KOMITE KREDIT
B7: DIUSULKAN DAN MENYETUJUI | F7: CATATAN:
B8: Tanggal | C8: : | D8: ='DATA AWAL NASABAH'!B1 -> 45986 | F8: 1. | G8: NASABAH BEKARAKTER BAIK | I8: PENYEDIA DATA
B9: Jaminan | C9: : | D9: SHM/NO.01798 & SHM/NO.00817 | F9: 2. | G9: USAHA DEBITUR LANCAR
B10: NJOP | C10: : | D10: ='TANAH BANGUNAN'!D118+'TANAH BANGUNAN'!M118 -> 62167000 | F10: 3. | G10: PINJAMAN YANG KE | H10: =D13 -> 10
B11: Nilai Wajar Jaminan | C11: : | D11: ='TANAH BANGUNAN'!H118+'TANAH BANGUNAN'!Q118 -> 2755400000 | F11: 4. | G11: JAMINAN MENCOVER
B12: Nilai Taksasi Bank | C12: : | D12: ='TANAH BANGUNAN'!H119+'TANAH BANGUNAN'!Q119 -> 2066550000 | F12: 5. | G12: PENURUNAN PLAFON
B13: Pengambilan ke | C13: : | D13: ='DATA AWAL NASABAH'!B31 -> 10
B14: Tujuan penggunaan | C14: : | D14: ='DATA AWAL NASABAH'!B29 -> INVESTASI PEMBELIAN TANAH
B15: Plafon | C15: : | D15: ='DATA AWAL NASABAH'!B18 -> 2000000000 | I15: ='DATA AWAL NASABAH'!B30 -> ADRIAN WAHYU P
B16: Jangka Waktu | C16: : | D16: ='DATA AWAL NASABAH'!B19 -> 12 | I16: ANALIS
B17: Sistem angsuran | C17: : | D17: TEMPO
B18: Suku Bunga | C18: : | D18: ='DATA AWAL NASABAH'!B20 -> 0.015
B19: Angsuran Bunga 1 | C19: : | D19: =D15*D18 -> 30000000
B20: Angsuran Bunga 2 | C20: : | D20: =D19 -> 30000000
B21: Angsuran Bunga 3 | C21: : | D21: =D20 -> 30000000
B22: Angsuran Bunga 4 | C22: : | D22: =D21 -> 30000000
B23: Angsuran Bunga 5 | C23: : | D23: =D22 -> 30000000
B24: Angsuran Bunga 6 | C24: : | D24: =D23 -> 30000000
B25: Angsuran Bunga 7 | C25: : | D25: =D24 -> 30000000
B26: Angsuran Bunga 8 | C26: : | D26: =D25 -> 30000000
B27: Angsuran Bunga 9 | C27: : | D27: =D26 -> 30000000
B28: Angsuran Bunga 10 | C28: : | D28: =D27 -> 30000000
B29: Angsuran Bunga 11 | C29: : | D29: =D28 -> 30000000
B30: Angsuran Bunga 12 | C30: : | D30: =D29 -> 30000000
B31: Jumlah Angsuran Bunga | C31: : | D31: =SUM(D19:D30) -> 360000000
B32: Jumlah Angsuran Pokok | C32: : | D32: =D15 -> 2000000000
B33: Jml Angsuran | C33: : | D33: =D32+D31 -> 2360000000
B34: OPINI
I35: MENYETUJUI
I40: NUROHMAN
I41: Kabag Analis
B42: OPINI
I43: MENYETUJUI
I48: RAAFI PURNA AJI
I49: Kabag Kredit
B50: OPINI
...

Sheet KOMITE FLAT
B2: NAMA | C2: : | D2: ='KOMITE ANUITAS'!D2:F2 -> DYAH RETNO SULISTYOWATI
B3: ALAMAT | C3: : | D3: ='KOMITE ANUITAS'!D3 -> TOSARI REJO 001/006 JARAKSARI WONOSOBO
B4: Jenis pekerjaan | C4: : | D4: ='KOMITE ANUITAS'!D4:F4 -> PNS
B5: KEPUTUSAN KOMITE KREDIT
B7: DIUSULKAN DAN MENYETUJUI | F7: CATATAN:
B8: Tanggal | C8: : | D8: ='DATA AWAL NASABAH'!B1 -> 45986 | F8: 1. | G8: NASABAH BEKARAKTER BAIK | J8: PENGUSUL
B9: Jaminan | C9: : | D9: ='TANAH BANGUNAN'!M16 -> SHM/NO.01565 | F9: 2. | G9: USAHA DEBITUR LANCAR
B10: NJOP | C10: : | D10: ='TANAH BANGUNAN'!M46 -> 356725000 | F10: 3. | G10: PINJAMAN YANG KE | H10: =D13 -> 10
B11: Nilai Jaminan | C11: : | D11: ='TANAH BANGUNAN'!Q46 -> 1489400000 | F11: 4. . | G11: JAMINAN MENCOVER
B12: Nilai Taksasi | C12: : | D12: ='TANAH BANGUNAN'!Q47 -> 1.04258e+09 | F12: 5.. | G12: ADA PELUNASAN PINJAMAN LAMA
B13: Pengambilan ke | C13: : | D13: ='DATA AWAL NASABAH'!B31 -> 10
B14: Tujuan penggunaan | C14: : | D14: ='DATA AWAL NASABAH'!B29 -> INVESTASI PEMBELIAN TANAH
B15: Plafon | C15: : | D15: ='DATA AWAL NASABAH'!B18 -> 2000000000
B16: Jangka Waktu | C16: : | D16: ='DATA AWAL NASABAH'!B19 -> 12
B17: Sistem angsuran | C17: : | D17: FLAT | J17: ='DATA AWAL NASABAH'!B30 -> ADRIAN WAHYU P
B18: Suku Bunga | C18: : | D18: ='DATA AWAL NASABAH'!B20 -> 0.015 | J18: Analis
B19: Angsuran Pokok | C19: : | D19: =D15/D16 -> 1.6666667e+08
B20: Angsuran Bunga | C20: : | D20: =D15*D18 -> 30000000
B21: Jml Angsuran | C21: : | D21: =D19+D20 -> 1.9666667e+08
B23: OPINI
J24: INVESTIGATOR
J31: BANGUN AJI WIRATMOKO
J32: Kabag. Analis
B34: OPINI
J35: MENYETUJUI
J41: RIFQY DEWANGGA, S.H
J42: Kadiv. Operasional
B44: KEPUTUSAN | C44: : | D44: DISETUJUI | E44: / | F44: DITOLAK | H44: / | I44: DISETUJUI TIDAK SESUAI PERMOHONAN
B45: Tanggal | C45: :
B46: Jaminan | C46: :
B47: NJOP | C47: :
B48: Nilai Jaminan | C48: :
B49: =B12 -> Nilai Taksasi | C49: :
B50: Pengambilan ke | C50: :
B51: Tujuan penggunaan | C51: :
B52: Plafon | C52: :
B53: Jangka Waktu | C53: :
B54: Sistem angsuran | C54: :
B55: Suku Bunga | C55: :
B56: Angsuran Pokok | C56: :
...

Sheet ADENDUM
B2: NAMA | C2: : | D2: ='DATA AWAL NASABAH'!B2 -> DYAH RETNO SULISTYOWATI
B3: ALAMAT | C3: : | D3: ='DATA AWAL NASABAH'!B21 -> TOSARI REJO 001/006 JARAKSARI WONOSOBO
B4: Jenis pekerjaan | C4: : | D4: ='DATA AWAL NASABAH'!B4 -> PNS
B5: KEPUTUSAN KOMITE KREDIT
B7: USULAN KOMITE LAMA | F7: USULAN KOMITE BARU
B8: Tanggal | C8: : | D8: ='DATA AWAL NASABAH'!B1 -> 45986 | G8: Tanggal | H8: : | I8: ='DATA AWAL NASABAH'!B1 -> 45986 | J8: PENGUSUL
B9: Jaminan | C9: : | D9: ='TANAH BANGUNAN'!M16 -> SHM/NO.01565 | G9: Jaminan | H9: : | I9: =D9 -> SHM/NO.01565
D10: ='TANAH BANGUNAN'!D16 -> SHM/NO.01562 | I10: =D10 -> SHM/NO.01562
B11: NJOP | C11: : | G11: NJOP | H11: : | I11: ='TANAH BANGUNAN'!M46+'TANAH BANGUNAN'!D46 -> 713450000
B12: Nilai Jaminan | C12: : | D12: ='TANAH BANGUNAN'!Q46+'TANAH BANGUNAN'!H46 -> 2883600000 | G12: Nilai Jaminan | H12: : | I12: =D12 -> 2883600000
B13: Nilai Taksasi | C13: : | D13: ='TANAH BANGUNAN'!Q47+'TANAH BANGUNAN'!H47 -> 2.01852e+09 | G13: Nilai Taksasi | H13: : | I13: =D13 -> 2.01852e+09
B14: Pengambilan ke | C14: : | D14: ='DATA AWAL NASABAH'!B31 -> 10 | G14: Pengambilan ke | H14: : | I14: =D14 -> 10 | N14: ='DATA AWAL NASABAH'!B20 -> 0.015
B15: Tujuan penggunaan | C15: : | D15: ='DATA AWAL NASABAH'!B29 -> INVESTASI PEMBELIAN TANAH | G15: Tujuan penggunaan | H15: : | I15: =D15 -> INVESTASI PEMBELIAN TANAH | N15: x POKOK BULAN SEBELUMNYA
B16: Plafon | C16: : | D16: ='DATA AWAL NASABAH'!B18 -> 2000000000 | G16: Plafon | H16: : | I16: =D16 -> 2000000000 | J16: ='DATA AWAL NASABAH'!B30 -> ADRIAN WAHYU P
B17: Jangka Waktu | C17: : | D17: 96 | G17: Jangka Waktu | H17: : | I17: 12 | J17: Analis
B18: Sistem angsuran | C18: : | D18: ANUITAS | G18: Sistem angsuran | H18: : | I18: TEMPO MENURUN
B19: Suku bunga | C19: : | D19: 0.115 | G19: Suku bunga | H19: : | I19: 1.5% X POKOK BULAN SEBELUMNYA
B20: Angsuran | C20: : | D20: =-PMT(D$19/12,$D$17,D16) -> 31958748 | G20: Angsuran | H20: : | I20: =I16*N14 -> 30000000
B22: OPINI
J23: INVESTIGATOR
J28: BANGUN AJI WIRATMOKO
J29: Kabag. Analis
B31: KEPUTUSAN | C31: : | D31: DISETUJUI | E31: / | F31: DITOLAK | H31: / | I31: DISETUJUI TIDAK SESUAI PLAFON
B32: Tanggal | C32: :
B33: Jaminan | C33: :
B34: NJOP | C34: :
B35: Nilai Jaminan | C35: :
B36: =B13 -> Nilai Taksasi | C36: :
B37: Pengambilan ke | C37: :
B38: Tujuan penggunaan | C38: :
B39: Plafon | C39: :
B40: Jangka Waktu | C40: :
B41: Sistem angsuran | C41: :
B42: Suku bunga | C42: :
B43: Angsuran | C43: :
B45: CATATAN
J46: MENYETUJUI
J51: RIFQY DEWANGGA, S.H
J52: YMT. Direktur Utama
B53: CATATAN
...

Sheet KOMITE ANUITAS
B2: NAMA | C2: : | D2: ='DATA AWAL NASABAH'!B2 -> DYAH RETNO SULISTYOWATI
B3: ALAMAT | C3: : | D3: ='DATA AWAL NASABAH'!B21 -> TOSARI REJO 001/006 JARAKSARI WONOSOBO
B4: Jenis pekerjaan | C4: : | D4: ='DATA AWAL NASABAH'!B4 -> PNS
B5: KEPUTUSAN KOMITE KREDIT
B7: DIUSULKAN DAN MENYETUJUI | F7: CATATAN:
B8: Tanggal | C8: : | D8: ='DATA AWAL NASABAH'!B1 -> 45986 | F8: 1. | G8: NASABAH BERKARAKTER BAIK | J8: PENGUSUL
B9: Jaminan | C9: : | D9: ='TANAH BANGUNAN'!M16 -> SHM/NO.01565 | F9: 2. | G9: USAHA DEBITUR LANCAR
D10: ='TANAH BANGUNAN'!D16 -> SHM/NO.01562 | F10: 3. | G10: PINJAMAN KE | H10: =D14 -> 10
B11: NJOP | C11: : | D11: ='TANAH BANGUNAN'!M46+'TANAH BANGUNAN'!D46 -> 713450000 | F11: 4. | G11: JAMINAN MENCOVER
B12: Nilai Jaminan | C12: : | D12: ='TANAH BANGUNAN'!Q46+'TANAH BANGUNAN'!H46 -> 2883600000
B13: Nilai Taksasi | C13: : | D13: ='TANAH BANGUNAN'!Q47+'TANAH BANGUNAN'!H47 -> 2.01852e+09
B14: Pengambilan ke | C14: : | D14: ='DATA AWAL NASABAH'!B31 -> 10
B15: Tujuan penggunaan | C15: : | D15: ='DATA AWAL NASABAH'!B29 -> INVESTASI PEMBELIAN TANAH
B16: Plafon | C16: : | D16: ='DATA AWAL NASABAH'!B18 -> 2000000000 | J16: ='DATA AWAL NASABAH'!B30 -> ADRIAN WAHYU P
B17: Jangka Waktu | C17: : | D17: ='DATA AWAL NASABAH'!B19 -> 12 | J17: Analis
B18: Sistem angsuran | C18: : | D18: ANUITAS
B19: Suku bunga | C19: : | D19: ='DATA AWAL NASABAH'!B20 -> 0.015
B20: Angsuran | C20: : | D20: =-PMT(D$19/12,$D$17,D16) -> 1.6802393e+08
B22: OPINI
J23: INVESTIGATOR
J28: BANGUN AJI WIRATMOKO
J29: Kabag. Analis
B30: OPINI
J31: MENYETUJUI
J36: RIFQY DEWANGGA, S.H
J37: Kadiv. Operasional
B39: KEPUTUSAN | C39: : | D39: DISETUJUI | E39: / | F39: DITOLAK | H39: / | I39: DISETUJUI TIDAK SESUAI PLAFON
B40: Tanggal | C40: :
B41: Jaminan | C41: :
B42: NJOP | C42: :
B43: Nilai Jaminan | C43: :
B44: =B13 -> Nilai Taksasi | C44: :
B45: Pengambilan ke | C45: :
B46: Tujuan penggunaan | C46: :
B47: Plafon | C47: :
B48: Jangka Waktu | C48: :
B49: Sistem angsuran | C49: :
B50: Suku bunga | C50: :
B51: Angsuran | C51: :
B53: CATATAN
...

Sheet TANAH BANGUNAN
B1: PT. BPR BANK WONOSOBO (PERSERODA) | K1: PT. BPR BANK WONOSOBO (PERSERODA)
B2: LAPORAN HASIL PENILAIAN TANAH DAN BANGUNAN | K2: LAPORAN HASIL PENILAIAN TANAH DAN BANGUNAN
B4: Nama Debitur | C4: : | D4: =M4 -> DYAH RETNO SULISTYOWATI | K4: Nama Debitur | L4: : | M4: ='DATA AWAL NASABAH'!B2 -> DYAH RETNO SULISTYOWATI
B5: No HP | C5: : | D5: =M5 -> 0811261088 | K5: No HP | L5: : | M5: ='DATA AWAL NASABAH'!B15 -> 0811261088
B6: Tgl Pemeriksaan | C6: : | D6: =M6 -> 45986 | K6: Tgl Pemeriksaan | L6: : | M6: ='DATA AWAL NASABAH'!B1 -> 45986
B7: Alamat Agunan | C7: : | D7: =""&D10&" "&D11 -> ROJOIMO WONOSOBO | K7: Alamat Agunan | L7: : | M7: =""&M10&" "&M11 -> ROJOIMO WONOSOBO
B9: LOKASI | F9: BATAS TANAH | K9: LOKASI | O9: BATAS TANAH
B10: Kelurahan | C10: : | D10: ROJOIMO | F10: Depan | G10: : | H10: JALAN | K10: Kelurahan | L10: : | M10: ROJOIMO | O10: Depan | P10: : | Q10: JALAN
B11: Kecamatan | C11: : | D11: WONOSOBO | F11: Belakang | G11: : | H11: JUPRIANTO | K11: Kecamatan | L11: : | M11: WONOSOBO | O11: Belakang | P11: : | Q11: JUPRIANTO
B12: Kabupaten | C12: : | D12: WONOSOBO | F12: Kiri | G12: : | H12: 00693 | K12: Kabupaten | L12: : | M12: WONOSOBO | O12: Kiri | P12: : | Q12: KUAT
B13: Lebar Jalan Masuk | C13: : | D13: 6M | F13: Kanan | G13: : | H13: 00689 | K13: Lebar Jalan Masuk | L13: : | M13: 6M | O13: Kanan | P13: : | Q13: 00690
B15: STATUS TANAH DAN BANGUNAN | K15: STATUS TANAH DAN BANGUNAN
B16: Jenis Surat Tanah / No | C16: : | D16: SHM/NO.01562 | F16: No IMB | G16: : | H16: - | K16: Jenis Surat Tanah / No | L16: : | M16: SHM/NO.01565 | O16: No IMB | P16: : | Q16: -
B17: Atas Nama | C17: : | D17: DYAH RETNO SULISTYOWATI | F17: Akta Jual Beli / Nomor | G17: : | H17: - | K17: Atas Nama | L17: : | M17: DYAH RETNO SULISTYOWATI | O17: Akta Jual Beli / Nomor | P17: : | Q17: -
B18: Dikeluarkan Oleh / Tgl | C18: : | D18: BPN/18-12-2014 | F18: Ditempati Oleh | G18: : | H18: DEBITUR | K18: Dikeluarkan Oleh / Tgl | L18: : | M18: BPN/18-12-2014 | O18: Ditempati Oleh | P18: : | Q18: DEBITUR
B19: Berlaku sampai Dengan | C19: : | D19: - | F19: Dasar Menempati | G19: : | H19: PEMILIK | K19: Berlaku sampai Dengan | L19: : | M19: - | O19: Dasar Menempati | P19: : | Q19: PEMILIK
B21: KEADAAN TANAH | K21: KEADAAN TANAH
B22: Bentuk Tanah | C22: : | D22: PERSEGI PANJANG | F22: Permukaan tanah dr Jalan | G22: : | H22: SEJAJAR | K22: Bentuk Tanah | L22: : | M22: PERSEGI PANJANG | O22: Permukaan tanah dr Jalan | P22: : | Q22: SEJAJAR
B23: Jenis Tanah | C23: : | D23: TANAH PERUMAHAN | F23: Penggunaan saat Ini | G23: : | H23: RUKO | K23: Jenis Tanah | L23: : | M23: TANAH PERUMAHAN | O23: Penggunaan saat Ini | P23: : | Q23: RUKO
B25: KEADAAN BANGUNAN | F25: KOMPONEN BANGUNAN | K25: KEADAAN BANGUNAN | O25: KOMPONEN BANGUNAN
B26: TH Dibangun / Renovasi | C26: : | D26: 2016 | F26: Lantai | G26: : | H26: KERAMIK | K26: TH Dibangun / Renovasi | L26: : | M26: 2016 | O26: Lantai | P26: : | Q26: KERAMIK
B27: Jenis Bangunan / tingkat | C27: : | D27: PERMANEN/2 LANTAI | F27: Dinding | G27: : | H27: TEMBOK | K27: Jenis Bangunan / tingkat | L27: : | M27: PERMANEN/2 LANTAI | O27: Dinding | P27: : | Q27: TEMBOK
B28: Listrik (KWH) | C28: : | D28: ADA | F28: Kusen | G28: : | H28: ALUMUNIUM | K28: Listrik (KWH) | L28: : | M28: ADA | O28: Kusen | P28: : | Q28: ALUMUNIUM
B29: PDAM / Sumur | C29: : | D29: ADA | F29: Atap | G29: : | H29: DAK BETON | K29: PDAM / Sumur | L29: : | M29: ADA | O29: Atap | P29: : | Q29: DAK BETON
B31: SARANA UMUM | K31: SARANA UMUM
B32: Angkutan Umum | C32: : | D32: DEKAT | F32: Tempat Hiburan | G32: : | H32: DEKAT | K32: Angkutan Umum | L32: : | M32: DEKAT | O32: Tempat Hiburan | P32: : | Q32: DEKAT
B33: Pasar | C33: : | D33: SEDANG | F33: Perkantoran | G33: : | H33: DEKAT | K33: Pasar | L33: : | M33: SEDANG | O33: Perkantoran | P33: : | Q33: DEKAT
B34: Sekolah | C34: : | D34: DEKAT | F34: Pertokoan | G34: : | H34: DEKAT | K34: Sekolah | L34: : | M34: DEKAT | O34: Pertokoan | P34: : | Q34: DEKAT
B35: Rumah sakit / Puskesmas | C35: : | D35: DEKAT | F35: Sarana Olah Raga | G35: : | H35: DEKAT | K35: Rumah sakit / Puskesmas | L35: : | M35: DEKAT | O35: Sarana Olah Raga | P35: : | Q35: DEKAT
B37: HASIL PENILAIAN | K37: HASIL PENILAIAN
B38: SUMBER INFORMASI SPPT | F38: SUMBER INFORMASI MASYARAKAT | K38: SUMBER INFORMASI SPPT | O38: SUMBER INFORMASI MASYARAKAT
B39: Luas Tanah (M2) | C39: : | D39: 945 | F39: Luas Tanah (M2) | G39: : | H39: 137 | K39: Luas Tanah (M2) | L39: : | M39: 945 | O39: Luas Tanah (M2) | P39: : | Q39: 154 | V39: 291
B40: Harga Tanah per m2 | C40: : | D40: 335000 | F40: Harga Tanah per m2 | G40: : | H40: 5600000 | K40: Harga Tanah per m2 | L40: : | M40: 335000 | O40: Harga Tanah per m2 | P40: : | Q40: 5600000 | T40: =2998402908/291 -> 10303790 | V40: 7500000
B41: Nilai Wajar | C41: : | D41: =D40*D39 -> 316575000 | F41: Nilai Wajar | G41: : | H41: =H39*H40 -> 767200000 | K41: Nilai Wajar | L41: : | M41: =M40*M39 -> 316575000 | O41: Nilai Wajar | P41: : | Q41: =Q39*Q40 -> 862400000 | V41: =V39*V40 -> 2182500000
B42: Luas Bangunan | C42: : | D42: 110 | F42: Luas Bangunan 1 | G42: : | H42: 165 | K42: Luas Bangunan | L42: : | M42: 110 | O42: Luas Bangunan 1 | P42: : | Q42: 165
B43: Harga Bangunanper m2 | C43: : | D43: 365000 | F43: Luas Bangunan 2 | G43: : | H43: 0 | K43: Harga Bangunanper m2 | L43: : | M43: 365000 | O43: Luas Bangunan 2 | P43: : | Q43: 0
B44: =B41 -> Nilai Wajar | C44: : | D44: =D42*D43 -> 40150000 | F44: Harga Bangunanper m2 | G44: : | H44: 3800000 | K44: =K41 -> Nilai Wajar | L44: : | M44: =M42*M43 -> 40150000 | O44: Harga Bangunanper m2 | P44: : | Q44: 3800000
F45: =F41 -> Nilai Wajar | H45: =(H42+H43)*H44 -> 627000000 | O45: =O41 -> Nilai Wajar | Q45: =(Q42+Q43)*Q44 -> 627000000
B46: TOTAL NILAI WAJAR | C46: : | D46: =D41+D44 -> 356725000 | F46: TOTAL NILAI WAJAR | G46: : | H46: =H41+H45 -> 1394200000 | K46: TOTAL NILAI WAJAR | L46: : | M46: =M41+M44 -> 356725000 | O46: TOTAL NILAI WAJAR | P46: : | Q46: =Q41+Q45 -> 1489400000 | T46: =Q46+H46 -> 2883600000
B47: NILAI TAKSASI (70%) | C47: : | D47: =D46*70% -> 2.497075e+08 | F47: NILAI TAKSASI (70%) | G47: : | H47: =H46*70% -> 9.7594e+08 | K47: NILAI TAKSASI (70%) | L47: : | M47: =M46*70% -> 2.497075e+08 | O47: NILAI TAKSASI (70%) | P47: : | Q47: =Q46*70% -> 1.04258e+09
...

Sheet KENDARAAN
B1: PT. BPR BANK WONOSOBO (PERSERODA) | K1: PT. BPR BANK WONOSOBO (PERSERODA)
B2: LAPORAN HASIL PENILAIAN KENDARAAN BERMOTOR | K2: LAPORAN HASIL PENILAIAN KENDARAAN BERMOTOR
B4: Nama Debitur | C4: : | D4: =M4 -> DYAH RETNO SULISTYOWATI | K4: Nama Debitur | L4: : | M4: ='DATA AWAL NASABAH'!B2 -> DYAH RETNO SULISTYOWATI
B5: No HP | C5: : | D5: =M5 -> 0811261088 | K5: No HP | L5: : | M5: ='DATA AWAL NASABAH'!B15 -> 0811261088
B6: Tgl Pemeriksaan | C6: : | D6: =M6 -> 45986 | K6: Tgl Pemeriksaan | L6: : | M6: ='DATA AWAL NASABAH'!B1 -> 45986
B8: DATA PEMILIK AGUNAN | K8: DATA PEMILIK AGUNAN
B9: Nama Pemilik BPKB | C9: : | F9: Nama Pemilik saat Ini | G9: : | H9: =D4 -> DYAH RETNO SULISTYOWATI | K9: Nama Pemilik BPKB | L9: : | M9: CITRA PERMATASARI | O9: Nama Pemilik saat Ini | P9: : | Q9: =M4 -> DYAH RETNO SULISTYOWATI
B10: Alamat BPKB | C10: : | F10: Alamat Pemilik | G10: : | H10: =Q10 -> JARAKSARI WONOSOBO | K10: Alamat BPKB | L10: : | O10: Alamat Pemilik | P10: : | Q10: =""&Q12&" "&Q13 -> JARAKSARI WONOSOBO
B11: Dusun | C11: : | F11: Dusun | G11: : | H11: =Q11 -> TOSARI REJO | K11: Dusun | L11: : | O11: Dusun | P11: : | Q11: ='DATA AWAL NASABAH'!B11 -> TOSARI REJO
B12: kelurahan | C12: : | F12: kelurahan | G12: : | H12: =Q12 -> JARAKSARI | K12: kelurahan | L12: : | O12: kelurahan | P12: : | Q12: ='DATA AWAL NASABAH'!B12 -> JARAKSARI
B13: Kecamatan | C13: : | F13: Kecamatan | G13: : | H13: =Q13 -> WONOSOBO | K13: Kecamatan | L13: : | O13: Kecamatan | P13: : | Q13: ='DATA AWAL NASABAH'!B13 -> WONOSOBO
B14: Kabupaten | C14: : | F14: Kabupaten | G14: : | H14: WONOSOBO | K14: Kabupaten | L14: : | M14: WONOSOBO | O14: Kabupaten | P14: : | Q14: ='DATA AWAL NASABAH'!B14 -> WONOSOBO
B15: Kota | C15: : | F15: Kota | G15: : | H15: WONOSOBO | K15: Kota | L15: : | M15: WONOSOBO | O15: Kota | P15: : | Q15: WONOSOBO
B16: Tanggal Pembelian Kendaraan berdasarkan Kwitansi / jual beli terakhir | G16: : | H16: - | K16: Tanggal Pembelian Kendaraan berdasarkan Kwitansi / jual beli terakhir | P16: : | Q16: -
B18: SPESIFIKASI AGUNAN | K18: SPESIFIKASI AGUNAN
B19: Jenis | C19: : | F19: No BPKB | G19: : | K19: Jenis | L19: : | M19: SEPEDA MOTOR | O19: No BPKB | P19: : | Q19: K-08863228
B20: Merk/type | C20: : | F20: No Rangka | G20: : | K20: Merk/type | L20: : | M20: HONDA/NC11BF1D A/T | O20: No Rangka | P20: : | Q20: MH1JFD228DK517883
B21: Tahun/Warna | C21: : | F21: No Mesin | G21: : | K21: Tahun/Warna | L21: : | M21: 2013/PUTIH | O21: No Mesin | P21: : | Q21: JFD2E2515541
B22: No Polisi | C22: : | F22: Masa berlaku STNK | G22: : | K22: No Polisi | L22: : | M22: AA 4152 JP | O22: Masa berlaku STNK | P22: : | Q22: 45245
B23: Atas nama | C23: : | F23: Fungsi sehari hari | G23: : | K23: Atas nama | L23: : | M23: =M9 -> CITRA PERMATASARI | O23: Fungsi sehari hari | P23: : | Q23: PRIBADI
B24: Alamat | C24: : | F24: Faktur | G24: : | K24: Alamat | L24: : | M24: =M10 -> 0 | O24: Faktur | P24: : | Q24: -
B26: TANGGAL PENGECEKAN | C26: : | D26: =D6 -> 45986 | K26: TANGGAL PENGECEKAN | L26: : | M26: =M6 -> 45986
B27: GESEKAN NO MESIN | K27: GESEKAN NO MESIN
B29: GESEKAN NO RANGKA | K29: GESEKAN NO RANGKA
D31: SUMBER INDEKS / INFORMASI HARGA KENDARAAN DI PEROLEH DARI : | M31: SUMBER INDEKS / INFORMASI HARGA KENDARAAN DI PEROLEH DARI :
B32: NILAI HARGA WAJAR | C32: : | D32: 115000000 | F32: WWW.OLX.COM | K32: NILAI HARGA WAJAR | L32: : | M32: 8500000 | N32: 1 | O32: WWW.OLX.COM
B33: NILAI TAKSASI BANK 70% | C33: : | D33: =D32*70% -> 80500000 | F33: WWW.CARMUDI.CO.ID | K33: NILAI TAKSASI BANK 70% | L33: : | M33: =M32*70% -> 5950000 | N33: 2 | O33: WWW.CARMUDI.CO.ID
F34: RIZAL | G34: / | H34: PEDAGANG KENDARAAN | O34: RIZAL | P34: / | Q34: PEDAGANG KENDARAAN
F35: EKO | G35: / | H35: PEDAGANG KENDARAAN | N35: 3 | O35: EKO | P35: / | Q35: PEDAGANG KENDARAAN
B36: KETERANGAN KENDARAAN | K36: KETERANGAN KENDARAAN
B37: Fisik Kendaraan cukup baik, kondisi mesin kendaraan baik, perlengkapan kendaraan standar masih orisinil, kodisi kendaraan layak jalan dan harga jual masih tinggi serta nilai taksasi dapat mengcover pinjaman yang diajukan . | K37: Fisik Kendaraan cukup baik, kondisi mesin kendaraan baik, perlengkapan kendaraan standar masih orisinil, kodisi kendaraan layak jalan dan harga jual masih tinggi serta nilai taksasi dapat mengcover pinjaman yang diajukan .
B39: PENDAPAT PEMERIKSA TENTANG KONDISI AGUNAN | K39: PENDAPAT PEMERIKSA TENTANG KONDISI AGUNAN
B40: Kami telah melakukan peninjauan terhadap objek di atas, dan menurut kami Kendaraan tersebut LAYAK untuk dijadikan agunan kredit pada PT. BPR BANK WONOSOBO (PERSERODA) dengan plafon kredit (sebagai pertimbangan collateral) adalah Rp 80.500.000 Kami yakin bahwa objek yang dinilai adalah yang dimaksudkan oleh bank dan penilaian didasarkan pada data yang tersedia Hasil penilaian tidak dipengaruhi oleh kepentingan pribadi baik langsung maupun tidak langsung . | K40: Kami telah melakukan peninjauan terhadap objek di atas, dan menurut kami Kendaraan tersebut LAYAK untuk dijadikan agunan kredit pada PT. BPR BANK WONOSOBO (PERSERODA) dengan plafon kredit (sebagai pertimbangan collateral) adalah Rp 5.950.000 Kami yakin bahwa objek yang dinilai adalah yang dimaksudkan oleh bank dan penilaian didasarkan pada data yang tersedia Hasil penilaian tidak dipengaruhi oleh kepentingan pribadi baik langsung maupun tidak langsung .
B45: PENGUSUL | D45: INVESTIGATOR | F45: MENYETUJUI | H45: MENYETUJUI | K45: PENGUSUL | M45: INVESTIGATOR | O45: MENYETUJUI | Q45: MENYETUJUI
B49: =K49 -> ADRIAN WAHYU P | D49: BANGUN AJI WIRATMOKO | F49: RIFQY DEWANGGA, S.H | H49: NANI TRI ASTUTI, S.E, M.M | K49: ='DATA AWAL NASABAH'!B30 -> ADRIAN WAHYU P | M49: BANGUN AJI WIRATMOKO | O49: RIFQY DEWANGGA, S.H | Q49: NANI TRI ASTUTI, S.E, M.M
B50: =K50 -> Analis | D50: =M50 -> Kabag. Analis | F50: Kadiv. Operasional | H50: Direktur Utama | K50: ='TANAH BANGUNAN'!K63 -> Analis | M50: ='TANAH BANGUNAN'!M63 -> Kabag. Analis | O50: Kadiv. Operasional | Q50: Direktur Utama

Sheet KIOS
A1: PD. BPR BANK WONOSOBO | I1: PD. BPR BANK WONOSOBO
A2: LAPORAN HASIL PENILAIAN KIOS/ DASARAN/ LOS/ SEJENIS LAINNYA | I2: LAPORAN HASIL PENILAIAN KIOS/ DASARAN/ LOS/ SEJENIS LAINNYA
A4: Nama Debitur | B4: : | C4: ='DATA AWAL NASABAH'!B2 -> DYAH RETNO SULISTYOWATI | I4: Nama Debitur | J4: : | K4: =C4 -> DYAH RETNO SULISTYOWATI
A5: No HP | B5: : | C5: ='DATA AWAL NASABAH'!B15 -> 0811261088 | I5: No HP | J5: : | K5: =C5 -> 0811261088
A6: Tgl Pemeriksaan | B6: : | C6: ='DATA AWAL NASABAH'!B1 -> 45986 | I6: Tgl Pemeriksaan | J6: : | K6: ='DATA AWAL NASABAH'!B1 -> 45986
A7: Jenis Agunan | I7: Jenis Agunan
A8: Nomor Agunan | I8: Nomor Agunan
A9: Nama Pemilik Agunan | I9: Nama Pemilik Agunan
A10: Alamat Pemilik Agunan | B10: : | I10: Alamat Pemilik Agunan | J10: :
A11: Masa Berlaku Kios | E11: sampai dengan | I11: Masa Berlaku Kios | M11: sampai dengan
A13: LOKASI | E13: BATAS KIOS | I13: LOKASI | M13: BATAS KIOS
A14: Nama Pasar | B14: : | E14: Depan | F14: : | I14: Nama Pasar | J14: : | M14: Depan | N14: :
A15: Lokasi Kios (blok/No) | B15: : | E15: Belakang | F15: : | I15: Lokasi Kios (blok/No) | J15: : | M15: Belakang | N15: :
A16: Kota | B16: : | C16: WONOSOBO | E16: Kiri | F16: : | I16: Kota | J16: : | K16: WONOSOBO | M16: Kiri | N16: :
A17: Lebar Jalan | B17: : | E17: Kanan | F17: : | I17: Lebar Jalan | J17: : | M17: Kanan | N17: :
A19: KEADAAN BANGUNAN | E19: KOMPONEN BANGUNAN | I19: KEADAAN BANGUNAN | M19: KOMPONEN BANGUNAN
A20: TH Dibangun / Renovasi | B20: : | E20: Lantai | F20: : | G20: PLUR | I20: TH Dibangun / Renovasi | J20: : | K20: 2001 | M20: Lantai | N20: : | O20: PLUR
A21: Jenis Bangunan / Bertingkat | B21: : | C21: PERMANEN | E21: Dinding | F21: : | G21: PAPAN KAYU | I21: Jenis Bangunan / Bertingkat | J21: : | K21: PERMANEN | M21: Dinding | N21: : | O21: PAPAN KAYU
A22: Listrik (KWH) | B22: : | C22: ADA | E22: Kusen | F22: : | G22: PAPAN KAYU | I22: Listrik (KWH) | J22: : | K22: ADA | M22: Kusen | N22: : | O22: PAPAN KAYU
A23: PDAM / Sumur | B23: : | C23: TIDAK ADA | E23: Atap | F23: : | G23: SENG | I23: PDAM / Sumur | J23: : | K23: TIDAK ADA | M23: Atap | N23: : | O23: SENG
A25: SARANA UMUM | I25: SARANA UMUM
A26: Angkutan Umum | B26: : | C26: DEKAT | E26: Tempat Hiburan | F26: : | G26: DEKAT | I26: Angkutan Umum | J26: : | K26: DEKAT | M26: Tempat Hiburan | N26: : | O26: DEKAT
A27: Pasar | B27: : | C27: DEKAT | E27: Perkantoran | F27: : | G27: DEKAT | I27: Pasar | J27: : | K27: DEKAT | M27: Perkantoran | N27: : | O27: DEKAT
A28: Sekolah | B28: : | C28: DEKAT | E28: Pertokoan | F28: : | G28: DEKAT | I28: Sekolah | J28: : | K28: DEKAT | M28: Pertokoan | N28: : | O28: DEKAT
A29: Rumah sakit / Puskesmas | B29: : | C29: SEDANG | E29: Sarana Olah Raga | F29: : | G29: DEKAT | I29: Rumah sakit / Puskesmas | J29: : | K29: SEDANG | M29: Sarana Olah Raga | N29: : | O29: DEKAT
A31: HASIL PENILAIAN II | I31: HASIL PENILAIAN I
A32: SUMBER INFORMASI | E32: HASIL PENILAIAN I DAN II | F32: : | I32: SUMBER INFORMASI | M32: HASIL PENILAIAN I DAN II | N32: :
A33: Luas Kios (M2) II | B33: : | E33: SUMBER INFORMASI | F33: : | I33: Luas Kios (M2) I | J33: : | M33: SUMBER INFORMASI | N33: :
A34: Harga Kios per m2 | B34: : | E34: Luas Kios (M2) I DAN II | F34: : | I34: Harga Kios per m2 | J34: : | M34: Luas Kios (M2) I DAN II | N34: :
A35: TOTAL NILAI TAKSASI | B35: : | C35: =C33*C34 -> 0 | E35: Harga Kios per m2 | F35: : | I35: TOTAL NILAI TAKSASI | J35: : | K35: =K33*K34 -> 0 | M35: Harga Kios per m2 | N35: :
A36: NILAI LIKUIDASI BANK (75%) | B36: : | C36: =C35*75% -> 0 | E36: TOTAL NILAI TAKSASI | F36: : | G36: =G34*G35 -> 0 | I36: NILAI LIKUIDASI BANK (75%) | J36: : | K36: =K35*75% -> 0 | M36: TOTAL NILAI TAKSASI | N36: : | O36: =O34*O35 -> 0
E37: NILAI LIKUIDASI BANK (75%) | F37: : | G37: =G36*75% -> 0 | M37: NILAI LIKUIDASI BANK (75%) | N37: : | O37: =O36*75% -> 0
A38: PENDAPAT PEMERIKSA TENTANG KONDISI AGUNAN | I38: PENDAPAT PEMERIKSA TENTANG KONDISI AGUNAN
A39: Kami telah melakukan peninjauan terhadap objek di atas, dan menurut kami Kios tersebut LAYAK untuk dijadikan agunan kredit pada PD. BPR BANK WONOSOBO dengan plafon kredit (sebagai pertimbangan collateral) maksimal adalah Rp 150.000.000,- Kami yakin bahwa objek yang dinilai adalah yang dimaksudkan oleh bank dan penilaian didasarkan pada data yang tersedia Hasil penilaian tidak dipengaruhi oleh kepentingan pribadi baik langsung maupun tidak langsung | I39: Kami telah melakukan peninjauan terhadap objek di atas, dan menurut kami Kios tersebut LAYAK untuk dijadikan agunan kredit pada PD. BPR BANK WONOSOBO dengan plafon kredit (sebagai pertimbangan collateral) maksimal adalah Rp 150.000.000,- Kami yakin bahwa objek yang dinilai adalah yang dimaksudkan oleh bank dan penilaian didasarkan pada data yang tersedia Hasil penilaian tidak dipengaruhi oleh kepentingan pribadi baik langsung maupun tidak langsung
A45: PENGUSUL | C45: INVESTIGATOR | E45: MENYETUJUI | G45: MENYETUJUI | I45: PENGUSUL | K45: INVESTIGATOR | M45: MENYETUJUI | O45: MENYETUJUI
A49: ='DATA AWAL NASABAH'!#REF! -> #REF! | C49: AANG KUNAEFI USMAN | E49: GALIH PAMBAJENG | G49: YUFIANDY | I49: ='DATA AWAL NASABAH'!B30 -> ADRIAN WAHYU P | K49: AANG KUNAEFI USMAN | M49: GALIH PAMBAJENG | O49: YUFIANDY
A50: Account Officer | C50: Kasi Kredit | E50: Kadiv. Marketing | G50: Kadiv. Operasional | I50: Account Officer | K50: Kasi Kredit | M50: Kadiv. Marketing | O50: Kadiv. Operasional
A52: MENYETUJUI | I52: MENYETUJUI
A56: NANI TRI ASTUTI, SE | I56: NANI TRI ASTUTI, SE
A57: Direktur | I57: Direktur

Sheet CDD TDK SDRHN
A1: PT. BPR BANK WONOSOBO (PERSERODA)
A2: FORMULIR CUSTOMER DUE DILIGENCE (CDD) KREDIT
B3: PENGKINIAN DATA | F3: Walk In Customer | I3: BARU
A5: DATA PRIBADI/ PERORANGAN
A7: C.ID | D7: :
A8: Nama lengkap | D8: : | E8: ='DATA AWAL NASABAH'!B2 -> DYAH RETNO SULISTYOWATI
A9: jenis kelamin | D9: : | F9: Laki laki | I9: Perempuan
A10: Tempat, tanggal lahir | D10: : | E10: ='DATA AWAL NASABAH'!B3 -> WONOSOBO, 19-04-1978
A11: Nama gadis ibu kandung | D11: : | E11: ='DATA AWAL NASABAH'!B22 -> SRI MURTINI
A12: Status | D12: : | F12: Menikah | H12: Belum menikah | J12: Janda/Duda
A13: Jenis identitas diri | D13: : | F13: KTP | H13: Kartu Pelajar | J13: Paspor
A14: Nomor Identitas | D14: : | E14: ='DATA AWAL NASABAH'!B16 -> 3307095904780003
A15: Alamat sesuai identitas | D15: : | E15: ='DATA AWAL NASABAH'!H11 -> TOSARI REJO 001/006 JARAKSARI WONOSOBO WONOSOBO
A16: Alamat tempat tinggal saat ini | D16: : | E16: ='DATA AWAL NASABAH'!H11 -> TOSARI REJO 001/006 JARAKSARI WONOSOBO WONOSOBO
A17: No Telp rumah | D17: :
A18: Status tempat tinggal saat ini | D18: : | F18: Milik sendiri | H18: Orang Tua | J18: Dinas
F19: Lainnya
A20: No HP | D20: : | E20: ='DATA AWAL NASABAH'!B15 -> 0811261088
A21: Alamat Email | D21: : | E21: -
A22: Kewarganegaraan | D22: : | F22: WNI | H22: WNA, Sebutkan………………………………………………………….
A23: Kependudukan | D23: : | F23: Penduduk | H23: Bukan Penduduk
A24: Pendidikan terahir | D24: : | F24: SD | H24: SMP/SMA | J24: Akademi/D3
F25: S1/S2 | H25: S3 | J25: Lainnya………………………...
A26: Tujuan bertransaksi | D26: : | F26: Kredit | H26: Tab/Deposito | J26: Lainnya………………………...
A28: AHLI WARIS
A29: Nama | D29: : | E29: ='DATA AWAL NASABAH'!B6 -> AFIF NURHIDAYAT
A30: Tempat tanggal lahir | D30: : | E30: ='DATA AWAL NASABAH'!B7 -> WONOSOBO, 25-11-1970
A31: Alamat | D31: : | E31: ='DATA AWAL NASABAH'!H11 -> TOSARI REJO 001/006 JARAKSARI WONOSOBO WONOSOBO
A32: Pekerjaan | D32: : | E32: ='DATA AWAL NASABAH'!B8 -> BUPATI
A33: Hubungan dengan Nasabah | D33: : | E33: Ayah/Ibu | G33: Suami/Istri | H33: Anak
A34: No telp
A36: DATA PEKERJAAN DAN PENGHASILAN
A37: Nama perusahaan/instansi | D37: : | E37: ='DATA AWAL NASABAH'!B23 -> ALFAMART KALIBEBER MANGGISAN DAN ROJOIMO
A38: Alamat perusahaan/instansi | D38: : | E38: ='DATA AWAL NASABAH'!B24 -> MUDAL WONOSOBO
A39: No telp kantor | D39: : | E39: ='DATA AWAL NASABAH'!B25 -> 0
A40: No Faximile kantor | D40: : | E40: - | H40: Ext:
A41: Departemen/Bagian | D41: : | E41: ='DATA AWAL NASABAH'!B26 -> PERDAGANGAN
A42: Jabatan | D42: : | E42: ='DATA AWAL NASABAH'!B27 -> PEMILIK
A43: Bidang | D43: : | F43: Industri/Pabrik | H43: Konstruksi/Properti | J43: Guru/Dosen
F44: Perdagangan/Retail | H44: Pemerintahan | J44: Lainnya………………………...
...

Sheet PEMANTAUAN JULI 24
A2: PEMANTAUAN SLIK BULAN SEPTEMBER 2024 AN DYAH RETNO SULISTYOWATI
A4: AGUSTUS | D4: SEPTEMBER
A5: PEMBERI PINJAMAN | B5: BAKI DEBET | C5: KETERANGAN | D5: PEMBERI PINJAMAN | E5: BAKI DEBET | F5: KETERANGAN
A9: PINJAMAN BANK WONOSOBO | B9: 4000000000 | D9: =A9 -> PINJAMAN BANK WONOSOBO | E9: =B9 -> 4000000000 | F9: LANCAR
A13: TOTAL PINJAMAN | B13: =SUM(B9:B11) -> 4000000000 | D13: TOTAL PINJAMAN | E13: =SUM(E9:E11) -> 4000000000
A17: PEMANTAUAN SLIK BULAN SEPTEMBER 2024 AN AFIF NUR HIDAYAT (PENDAMPING)
A19: AGUSTUS | D19: SEPTEMBER
A20: PEMBERI PINJAMAN | B20: BAKI DEBET | C20: KETERANGAN | D20: PEMBERI PINJAMAN | E20: BAKI DEBET | F20: KETERANGAN
A24: PINJAMAN BANK CIMB NIAGA | B24: 350000 | D24: =A24 -> PINJAMAN BANK CIMB NIAGA | E24: =B24 -> 350000 | F24: LANCAR
A28: TOTAL PINJAMAN | B28: =SUM(B24:B26) -> 350000 | D28: TOTAL PINJAMAN | E28: =SUM(E24:E26) -> 350000

Sheet NERACA
A1: SEBELUM KREDIT | I1: SEBELUM KREDIT
A2: NERACA | I2: ANALISA USAHA
A4: AKTIVA | D4: PASIVA
I5: NAMA | J5: : | K5: ='DATA AWAL NASABAH'!B2 -> DYAH RETNO SULISTYOWATI
B6: TAHUN PEROLEHAN | C6: HARGA | I6: JENIS USAHA | J6: : | K6: ='DATA AWAL NASABAH'!B4 -> PNS
A7: KAS | C7: 5000000 | E7: PAJAK DAN PBB | F7: 10000000 | I7: ALAMAT USAHA | J7: : | K7: ='DATA AWAL NASABAH'!B21 -> TOSARI REJO 001/006 JARAKSARI WONOSOBO
A8: TABUNGAN | C8: 1900000000 | I8: LAMA USAHA | J8: : | K8: ='DATA AWAL NASABAH'!B28 -> LEBIH DARI 5 TAHUN
AC10: =SUM(#REF!)/2 -> #REF! | AE10: =ROUND(AC10,0) -> #REF!
A11: TANAH & BANGUNAN | K11: ALFAMART MIROMBO | AC11: =SUM(#REF!)/2 -> #REF! | AE11: =ROUND(AC11,0) -> #REF!
A12: RUMAH TINGGAL | B12: 2001 | C12: 1500000000 | K12: BULAN | L12: PENJUALAN | O12: BEBAN POKOK | P12: PENGHASILAN SEWA | Q12: BEBAN USAHA | R12: PENGHASILAN DILUAR USAHA | S12: BEBAN DILUAR USAHA | T12: BEBAN TRANS NON KAS | U12: LABA/RUGI
A13: GARASI | B13: 2003 | C13: 400000000 | E13: PINJAMAN BCA | F13: 30555556 | K13: AGUST 2025 | L13: 273852380 | O13: 228788761 | P13: 4500000 | Q13: 36792336 | R13: 2364400 | S13: 1327857 | T13: 8986284 | U13: =L13-O13+P13-Q13+R13-S13+T13 -> 22794110 | AC13: =SUM(#REF!)/2 -> #REF! | AE13: =ROUND(AC13,0) -> #REF!
A14: TANAH KALIBEBER | B14: 2017 | C14: 300000000 | E14: PINJAMAN BCA | F14: 3057328786 | K14: SEPT 2025 | L14: 268673801 | O14: 224833596 | P14: 4500000 | Q14: 31911840 | R14: 2382791 | S14: 826078 | T14: 2024641 | U14: =L14-O14+P14-Q14+R14-S14+T14 -> 20009719 | AC14: =SUM(#REF!)/2 -> #REF! | AE14: =ROUND(AC14,0) -> #REF!
A15: KOLAM TOSARIREJO | B15: 2016 | C15: 300000000 | E15: PINJAMAN BANK WONOSOBO | F15: 1643894213 | K15: OKT 2025 | L15: 286719261 | O15: 240919166 | P15: 4500000 | Q15: 32516335 | R15: 3813628 | S15: 1812422 | T15: 2058557 | U15: =L15-O15+P15-Q15+R15-S15+T15 -> 21843523
A16: ALFAMART KALIBEBER | B16: 2016 | C16: 1154000000 | E16: PINJAMAN CIMB NIAGA | F16: 700000 | K16: TOTAL | L16: =SUM(L13:N15) -> 829245442 | O16: =SUM(O13:O15) -> 694541523 | P16: =SUM(P13:P15) -> 13500000 | Q16: =SUM(Q13:Q15) -> 101220511 | R16: =SUM(R13:R15) -> 8560819 | S16: =SUM(S13:S15) -> 3966357 | T16: =SUM(T13:T15) -> 13069482 | U16: =SUM(U13:U15) -> 64647352
A17: ALFAMART MANGGISAN | B17: 2017 | C17: 980000000 | K17: RATA-RATA | L17: =L16/3 -> 2.7641515e+08 | O17: =O16/3 -> 231513841 | P17: =P16/3 -> 4500000 | Q17: =Q16/3 -> 33740170 | R17: =R16/3 -> 2853606.3 | S17: =S16/3 -> 1322119 | T17: =T16/3 -> 4356494 | U17: =U16/3 -> 21549117 | AC17: Plafon | AE17: 3350000000
A18: RUKO KALIBEBER | B18: 2017 | C18: 900000000 | E18: TOTAL PINJAMAN | F18: =SUM(F7:F16) -> 4742478555 | AC18: Jangka Waktu | AE18: 120
A19: RUKO ROJOIMO 1 | B19: 2019 | C19: ='TANAH BANGUNAN'!H46 -> 1394200000 | K19: ALFAMART MANGGISAN | AC19: Suku Bunga | AE19: 0.0625
A20: RUKO ROJOIMO 2 | B20: 2019 | C20: ='TANAH BANGUNAN'!Q46 -> 1489400000 | K20: BULAN | L20: PENJUALAN | O20: BEBAN POKOK | P20: PENGHASILAN SEWA | Q20: BEBAN USAHA | R20: PENGHASILAN DILUAR USAHA | S20: BEBAN DILUAR USAHA | T20: BEBAN TRANS NON KAS | U20: LABA/RUGI
K21: =K13 -> AGUST 2025 | L21: 318842630 | O21: 262576684 | P21: 4500000 | Q21: 32059824 | R21: 1910648 | S21: 673561 | T21: 2440606 | U21: =L21-O21+P21-Q21+R21-S21+T21 -> 32383815 | AC21: FLAT
K22: =K14 -> SEPT 2025 | L22: 343288849 | O22: 282978892 | P22: 4500000 | Q22: 37535515 | R22: 2147010 | S22: 707415 | T22: 2564556 | U22: =L22-O22+P22-Q22+R22-S22+T22 -> 31278593 | AC22: Plafon | AD22: : | AE22: =AE17 -> 3350000000
A23: KENDARAAN | K23: =K15 -> OKT 2025 | L23: 288726954 | O23: 240102493 | P23: 4500000 | Q23: 33380900 | R23: 1928653 | S23: 686516 | T23: 2654911 | U23: =L23-O23+P23-Q23+R23-S23+T23 -> 23640609 | AC23: Jangka Waktu | AD23: : | AE23: =AE18 -> 120
A24: HONDA HRV PRESTIGE 2016 | B24: 2016 | C24: 275000000 | K24: TOTAL | L24: =SUM(L21:N23) -> 950858433 | O24: =SUM(O21:O23) -> 785658069 | P24: =SUM(P21:P23) -> 13500000 | Q24: =SUM(Q21:Q23) -> 102976239 | R24: =SUM(R21:R23) -> 5986311 | S24: =SUM(S21:S23) -> 2067492 | T24: =SUM(T21:T23) -> 7660073 | U24: =SUM(U21:U23) -> 87303017 | AC24: Sistem angsuran | AD24: : | AE24: FLAT
K25: RATA-RATA | L25: =L24/3 -> 316952811 | O25: =O24/3 -> 261886023 | P25: =P24/3 -> 4500000 | Q25: =Q24/3 -> 34325413 | R25: =R24/3 -> 1995437 | S25: =S24/3 -> 689164 | T25: =T24/3 -> 2553357.7 | U25: =U24/3 -> 29101006 | AC25: Suku Bunga | AD25: : | AE25: =AE19 -> 0.0625 | AF25: =AE25/12 -> 0.0052083333
E26: MODAL | F26: =B30-F18 -> 9855121445 | AC26: Angsuran Pokok | AD26: : | AE26: =AE22/AE23 -> 27916667
A27: STOK BARANG DAGANG | C27: 4000000000 | K27: ALFAMART KALIBEBER | AC27: Angsuran Bunga | AD27: : | AE27: =AE22*AF25 -> 17447917
K28: BULAN | L28: PENJUALAN | O28: BEBAN POKOK | P28: PENGHASILAN SEWA | Q28: BEBAN USAHA | R28: PENGHASILAN DILUAR USAHA | S28: BEBAN DILUAR USAHA | T28: BEBAN TRANS NON KAS | U28: LABA/RUGI | AC28: Jml Angsuran | AD28: : | AE28: =AE26+AE27 -> 45364583
K29: =K21 -> AGUST 2025 | L29: 378165149 | O29: 313892071 | P29: 4500000 | Q29: 37204285 | R29: 2229300 | S29: 819169 | T29: 1927478 | U29: =L29-O29+P29-Q29+R29-S29+T29 -> 34906402
A30: JUMLAH | B30: =SUM(C7:C27) -> 14597600000 | D30: JUMLAH | F30: =F26+F18 -> 14597600000 | K30: =K22 -> SEPT 2025 | L30: 405485707 | O30: 335160124 | P30: 4500000 | Q30: 39231269 | R30: 2191580 | S30: 890335 | T30: 1927478 | U30: =L30-O30+P30-Q30+R30-S30+T30 -> 38823037
K31: =K23 -> OKT 2025 | L31: 398411891 | O31: 333225859 | P31: 4500000 | Q31: 34093735 | R31: 2247276 | S31: 850841 | T31: 2019810 | U31: =L31-O31+P31-Q31+R31-S31+T31 -> 39008542
K32: TOTAL | L32: =SUM(L29:N31) -> 1182062747 | O32: =SUM(O29:O31) -> 982278054 | P32: =SUM(P29:P31) -> 13500000 | Q32: =SUM(Q29:Q31) -> 110529289 | R32: =SUM(R29:R31) -> 6668156 | S32: =SUM(S29:S31) -> 2560345 | T32: =SUM(T29:T31) -> 5874766 | U32: =SUM(U29:U31) -> 112737981 | AC32: Plafon | AD32: : | AE32: =AE17 -> 3350000000
K33: RATA-RATA | L33: =L32/3 -> 3.9402092e+08 | O33: =O32/3 -> 327426018 | P33: =P32/3 -> 4500000 | Q33: =Q32/3 -> 36843096 | R33: =R32/3 -> 2222718.7 | S33: =S32/3 -> 853448.33 | T33: =T32/3 -> 1958255.3 | U33: =U32/3 -> 37579327 | AC33: Jangka Waktu | AD33: : | AE33: =AE18 -> 120
A34: SESUDAH KREDIT | AC34: Sistem angsuran | AD34: : | AE34: ANUITAS
A35: NERACA | AC35: Suku bunga | AD35: : | AE35: =AE19 -> 0.0625
I36: USAHA INTI | J36: ALFAMART KALIBEBER, MANGGISAN, & MIROMBO | AC36: Angsuran | AD36: : | AE36: =-PMT(AE35/12,AE33,AE32) -> 37613832
A37: AKTIVA | D37: PASIVA | J37: Omset Penjualan / Bulan | X37: /BL | Y37: = | Z37: Rp | AA37: =U17+U25+U33 -> 88229450
K38: Keuntungan | AA38: =AA37 -> 88229450
B39: TAHUN PEROLEHAN | C39: HARGA
A40: KAS | C40: 5000000 | E40: PAJAK DAN PBB | F40: 10000000 | I40: PENDAPATAN LAIN
A41: TABUNGAN | C41: =F48-F15 -> 356105787
J42: KEUNTUNGAN BERSIH | X42: /BL | Y42: = | Z42: Rp | AA42: =AA38 -> 88229450 | AE42: =1500000000*1.5% -> 22500000
...

Sheet 6 C
A1: NAMA | B1: : | C1: ='DATA AWAL NASABAH'!B2 -> DYAH RETNO SULISTYOWATI
A2: ALAMAT | B2: : | C2: ='DATA AWAL NASABAH'!B21 -> TOSARI REJO 001/006 JARAKSARI WONOSOBO
A3: Jenis pekerjaan : | C3: ='DATA AWAL NASABAH'!B4 -> PNS
A5: CHARACTER | C5: NILAI | D5: BOBOT RESIKO | J5: CAPACITY
D6: 5 | E6: 4 | F6: 3 | G6: 2 | H6: 1 | J6: Repayment Capacity x 100
A7: No | B7: Tolak Ukur | C7: Resiko | D7: Sangat Baik | E7: Baik | F7: Cukup Baik | G7: Kurang Baik | H7: Tidak Baik | J7: Jumlah/rencana angsuran
A8: 1 | B8: Kejujuran, keterbukaan dan kooperatif | E8: 4
A9: 2 | B9: Slik / BI Cheking | E9: 4 | J9: =ANALISIS!D42 -> 36801779 | L9: X | M9: 100
A10: 3 | B10: Persoalan Hukum/Tindak Pidana | E10: 4 | J10: =ADENDUM!I20 -> 30000000
A11: 4 | B11: Gaya Hidup | E11: 4
A12: 5 | B12: Latar Belakang Keluarga | E12: 4 | J12: =(J9/J10)*M9 -> 122.6726
A13: 6 | B13: Kesanggupan dalam melengkapi dokumen | E13: 4
A14: 7 | B14: Tujuan Penggunaan Pinjaman | E14: 4
B15: Total Resiko | C15: =SUM(D15:H15)/7 -> 4 | D15: =SUM(D8:D14) -> 0 | E15: =SUM(E8:E14) -> 28 | F15: =SUM(F8:F14) -> 0 | G15: =SUM(G8:G14) -> 0 | H15: =SUM(H8:H14) -> 0
A17: CAPITAL
A18: TOTAL ASSET | E18: X | F18: 100 | G18: = | H18: =NERACA!B30 -> 14597600000 | J18: X | K18: 100
A19: total hutang | H19: =NERACA!F18 -> 4742478555
G20: = | H20: =H18/H19*K18 -> 307.80529
A24: NAMA | B24: : | C24: =C1 -> DYAH RETNO SULISTYOWATI
A25: ALAMAT | B25: : | C25: =C2 -> TOSARI REJO 001/006 JARAKSARI WONOSOBO
A26: Jenis pekerjaan : | C26: =C3 -> PNS
A27: CONDITION OF ECONOMY | C27: NILAI | D27: BOBOT RESIKO
D28: 5 | E28: 4 | F28: 3 | G28: 2 | H28: 1
A29: No | B29: Tolak Ukur | C29: Resiko | D29: Sangat Baik | E29: Baik | F29: Cukup Baik | G29: Kurang Baik | H29: Tidak Baik
A30: 1 | B30: Rumah tinggal calon nasabah bukan rumah tinggal sementara. | E30: 4
A31: 2 | B31: Memiliki tempat usaha yang strategis dan ekonomis. | E31: 4
A32: 3 | B32: Memiliki ijin usaha atau legalitas usaha bagi pengusaha dan memiliki sarana dan prasarana yang memadai | E32: 4
A33: 4 | B33: Memiliki Karyawan | E33: 4
A34: 5 | B34: Tidak banyak memiliki beban rumah tangga dan beban angsuran. | E34: 4
B35: Total Resiko | C35: =SUM(D35:H35)/5 -> 4 | D35: =SUM(D30:D34) -> 0 | E35: =SUM(E30:E34) -> 20 | F35: =SUM(F30:F34) -> 0 | G35: =SUM(G30:G34) -> 0 | H35: =SUM(H30:H34) -> 0
A36: COLLATERAL
A37: TOTAL NILAI JAMINAN
E38: X | F38: 100 | G38: = | H38: ='KOMITE TEMPO'!D12 -> 2066550000 | J38: X | K38: 100 | L38: = | M38: =H38/H39*K38 -> 103.3275
A39: JUMLAH PLAFOND | H39: ='DATA AWAL NASABAH'!B18 -> 2000000000
B48: CAPACITY
B49: =IF(J12>=150,"5",IF(J12>=125,"4",IF(J12>=100,"3",IF(J12>=75,"1")))) -> 3
B51: CAPITAL
B52: =IF(H20>=500,"5",IF(H20>=400,"4",IF(H20>=300,"3",IF(H20>=200,"2",IF(H20>=100,"1"))))) -> 3
B54: COLATERAL
B55: =IF(M38>=150,"5",IF(M38>=125,"4",IF(M38>=100,"3",IF(M38>=75,"1")))) -> 3
...

Sheet SCORE
A2: NAMA | B2: : | D2: ='DATA AWAL NASABAH'!B2 -> DYAH RETNO SULISTYOWATI
A3: ALAMAT | B3: : | D3: ='DATA AWAL NASABAH'!B21 -> TOSARI REJO 001/006 JARAKSARI WONOSOBO
A4: Jenis pekerjaan | B4: : | D4: ='DATA AWAL NASABAH'!B4 -> PNS
A5: Tanggal | B5: : | D5: ='DATA AWAL NASABAH'!B1 -> 45986
P6: ='6 C'!C15 -> 4
A7: CHARACTER | D7: CAPACITY | H7: CAPITAL | J7: CONDITION OF ECONOMY | L7: COLATERAL
A8: PENILAIAN | B8: ='6 C'!B58 -> 4 | D8: PENILAIAN | F8: ='6 C'!B49 -> 3 | H8: PENILAIAN | I8: ='6 C'!B52 -> 3 | J8: PENILAIAN | K8: ='6 C'!B61 -> 4 | L8: PENILAIAN | M8: ='6 C'!B55 -> 3
A9: AHIR | D9: AHIR | H9: AHIR | J9: AHIR | L9: AHIR | P9: =ROUND(P6,0) -> 4
A10: PENILAIAN | B10: BOBOT | D10: PENILAIAN | F10: BOBOT | H10: PENILAIAN | I10: BOBOT | J10: PENILAIAN | K10: BOBOT | L10: PENILAIAN | M10: BOBOT
A11: SGT BAIK | B11: 5 | D11: > 150 | F11: 5 | H11: > 500 | I11: 5 | J11: SGT BAIK | K11: 5 | L11: > 150 | M11: 5
A12: BAIK | B12: 4 | D12: 125-149 | F12: 4 | H12: 400-499 | I12: 4 | J12: BAIK | K12: 4 | L12: 125-149 | M12: 4
A13: CKP BAIK | B13: 3 | D13: 100-124 | F13: 3 | H13: 300-399 | I13: 3 | J13: CKP BAIK | K13: 3 | L13: 100-124 | M13: 3
A14: KRG BAIK | B14: 2 | D14: 75-99 | F14: 2 | H14: 200-299 | I14: 2 | J14: KRG BAIK | K14: 2 | L14: 75-99 | M14: 2
A15: TDK BAIK | B15: 1 | D15: < 74 | F15: 1 | H15: < 200 | I15: 1 | J15: TDK BAIK | K15: 1 | L15: < 74 | M15: 1
A17: KESIMPULAN AKHIR
A18: ASPEK | E18: NILAI | H18: BOBOT | I18: SCORE | K18: SCORE | L18: KEPUTUSAN
A19: CHARACTER | E19: =B8 -> 4 | H19: 0.2 | I19: =E19*H19 -> 0.8 | K19: 5 | L19: LAYAK SEKALI
A20: CAPACITY | E20: =F8 -> 3 | H20: 0.3 | I20: =E20*H20 -> 0.9 | K20: 4 - 4.9 | L20: LAYAK
A21: CAPITAL | E21: =I8 -> 3 | H21: 0.2 | I21: =E21*H21 -> 0.6 | K21: 3 - 3.9 | L21: LAYAK DENGAN CATATAN
A22: CONDITION OF ECONOMY | E22: =K8 -> 4 | H22: 0.1 | I22: =E22*H22 -> 0.4 | K22: < 2.9 | L22: DITOLAK
A23: COLLATERAL | E23: =M8 -> 3 | H23: 0.2 | I23: =E23*H23 -> 0.6
A24: JUMLAH | I24: =I19+I20+I21+I22+I23 -> 3.3 | K24: CATATAN | L24: MENGETAHUI | M24: TTD
K25: PASTIKAN PELUNASAN TEPAT WAKTU | L25: ANALIS
A26: SCORE | H26: =I24 -> 3.3 | L26: ='DATA AWAL NASABAH'!B30 -> ADRIAN WAHYU P
A27: LAYAK / TIDAK LAYAK DIBERI KREDIT DENGAN MAKSIMAL | H27: LAYAK | I27: TIDAK LAYAK | L27: MENYETUJUI
A28: PINJAMAN SEBESAR | H28: ='DATA AWAL NASABAH'!B18 -> 2000000000 | L28: NUROHMAN
A29: JANGKA WAKTU | H29: ='DATA AWAL NASABAH'!B19 -> 12 | L29: MENYETUJUI
A30: BUNGA | H30: ='DATA AWAL NASABAH'!B20 -> 0.015 | L30: RAAFI PURNA AJI
L31: MENYETUJUI
L32: RIFQY DEWANGGA, S.H
K39: =IF(I24>=5,"LAYAK SEKALI",IF(I24>=4,"LAYAK",IF(K25>=3,"MAINTENANCE ANGSURAN",IF(I24>=25,"TIDAK LAYAK")))) -> MAINTENANCE ANGSURAN

Sheet DENAH RUMAH
A2: DENAH RUMAH
A26: DENAH RUMAH
W38: 2013
W39: 1977
W40: =W38-W39 -> 36

Sheet BA NEGOSIASI
B2: BERITA ACARA NEGOSIASI ANTARA ANALIS DENGAN
B3: (Calon Peminjam/End User)
B6: Pada hari ini | E6: ='DATA AWAL NASABAH'!B1 -> 45986 | H6: telah dilakukan survey dan negosiasi antara petugas
B7: analis PT. BPR Bank Wonosobo (Perseroda) dengan calon peminjam.
B9: Yang bertandatangan dibawah ini :
B11: Nama | E11: : | F11: ='DATA AWAL NASABAH'!B2 -> DYAH RETNO SULISTYOWATI
B12: Jenis Usaha | E12: : | F12: ='DATA AWAL NASABAH'!B26 -> PERDAGANGAN
B13: Alamat | E13: : | F13: ='DATA AWAL NASABAH'!B10 -> TOSARI REJO 001/006 JARAKSARI WONOSOBO
B14: No KTP | E14: : | F14: ='DATA AWAL NASABAH'!B16 -> 3307095904780003
B16: Dengan ini menyatakan bahwa :
C18: 1. | D18: Benar, saya sebagai Nasabah/Calon Nasabah PT. BPR Bank Wonosobo (Perseroda) telah sepakat untuk mengajukan permohonan pinjaman dengan kesepakatan sebagai berikut :
D20: a) | E20: Plafond Pinjaman | G20: : | H20: ='DATA AWAL NASABAH'!B18 -> 2000000000
D21: b) | E21: Jangka Waktu Pinjaman | G21: : | H21: ='DATA AWAL NASABAH'!B19 -> 12 | I21: Bulan
D22: c) | E22: Suku Bunga Pinjaman | G22: : | H22: ='DATA AWAL NASABAH'!B20 -> 0.015 | I22: Perbulan
D23: d) | E23: Agunan Berupa | G23: : | H23: SHM
D24: e) | E24: Tujuan Penggunaan | G24: : | H24: ='DATA AWAL NASABAH'!B29 -> INVESTASI PEMBELIAN TANAH
D25: e) | E25: Sistem Angsuran | G25: : | H25: Tempo
F26: √ Flat
F27: √ Anuitas
F28: √ Tempo
C29: 2. | D29: Data dan informasi yang kami sampaikan baik saat wawancara maupun data pendukung pada saat kunjungan tim analis PT. BPR Bank Wonosobo (Perseroda) adalah BENAR tanpa adanya rekayasa atau fiktif.
C32: 3. | D32: Bahwa pengunaan kredit akan dipakai sendiri bukan atas nama, Apabila terdapat hal-hal yang tidak benar dikemudian hari terkait dengan data dan informasi yang kami sampaikan tersebut, maka kami bersedia bertanggung jawab secara hukum tanpa melibatkan pihak PT. BPR Bank Wonosobo (Perseroda) dan atau petugas kunjungan lapangan.
B37: Demikian surat pernyataan ini kami buat dan memiliki kekuatan hukum dan dapat untuk dipergunakan sebagaimana mestinya.
J40: Wonosobo | K40: =E6 -> 45986
J41: Calon Debitur / Debitur
J45: ( ……………………………………….. )
B46: Surveyor | D46: :
B47: Direksi | F47: : ………………………………………………………
B48: Kadiv Bisnis | F48: : ………………………………………………………
B49: Kabag Kredit | F49: : ………………………………………………………
B50: Kabag Analis | F50: : ………………………………………………………
B51: Analis | F51: : ………………………………………………………
O53: =2022-1971 -> 51

Sheet DEPOSITO
A1: PD. BPR BANK WONOSOBO
A2: LAPORAN HASIL PENILAIAN DEPOSITO
A4: Nama Debitur | B4: : | C4: ='DATA AWAL NASABAH'!B2 -> DYAH RETNO SULISTYOWATI
A5: No HP | B5: : | C5: ='DATA AWAL NASABAH'!B15 -> 0811261088
A6: Tgl Pemeriksaan | B6: : | C6: ='DATA AWAL NASABAH'!B1 -> 45986
A7: Alamat Agunan | B7: :
A9: SPESIFIKASI AGUNAN
A10: Nama Pemilik Agunan | B10: :
A11: Alamat Pemilik | B11: :
A12: Dusun | B12: : | E12: Kecamatan | F12: :
A13: kelurahan | B13: : | E13: Kabupaten | F13: :
A14: Rt / Rw | B14: : | E14: Kota | F14: :
A15: Hubungan Dengan Debitur | B15: : | E15: Nomor Bilyet | F15: :
A16: Bank Penerbit | B16: : | E16: Lokasi Bank Penerbit | F16: :
A17: Tanggal Penerbitan | B17: : | E17: Tanggal Jatuh Tempo | F17: :
A18: Nilai Nomonal Deposito | B18: : | E18: Nilai Likuidasi Bank 90% | F18: :
A20: PENDAPAT PEMERIKSA TENTANG KONDISI AGUNAN
A21: Kami telah melakukan peninjauan terhadap objek di atas, dan menurut kami Deposito tersebut LAYAK untuk dijadikan agunan kredit pada PD. BPR BANK WONOSOBO dengan plafon kredit (sebagai pertimbangan collateral) maksimal adalah Rp.......................................Kami yakin bahwa objek yang dinilai adalah yang dimaksudkan oleh bank dan penilaian didasarkan pada data yang tersedia Hasil penilaian tidak dipengaruhi oleh kepentingan pribadi baik langsung maupun tidak langsung
A27: PENGUSUL | C27: INVESTIGATOR | E27: MENYETUJUI | G27: MENYETUJUI
A31: ='DATA AWAL NASABAH'!B30 -> ADRIAN WAHYU P | C31: AANG KUNAEFI USMAN | E31: GALIH PAMBAJENG | G31: YUFIANDY
A32: Account Officer | C32: Kasi Kredit | E32: Kadiv. Marketing | G32: Kadiv. Operasional
A34: MENYETUJUI | J34: MENYETUJUI
A38: NANI TRI ASTUTI, SE
A39: Direktur | J39: (…………………………….)

Sheet CASH FLOW
B2: CASH FLOW
C4: 1 | D4: CIMB NIAGA
D5: JULI | E5: AGUSTUS | F5: SEPTEMBER | G5: OKTOBER
D6: 195536627 | E6: 21632143 | F6: 20979981 | G6: 37679981 | J6: =D6+E6+F6+G6 -> 275828732
D7: RATA - RATA | E7: =J6/4 -> 68957183
C9: 2 | D9: BCA
D10: JULI | E10: AGUSTUS | F10: SEPTEMBER | G10: OKTOBER
D11: 2435877 | E11: 1920822 | F11: 3888768 | G11: 334182 | J11: =D11+E11+F11+G11 -> 8579649
D12: =D7 -> RATA - RATA | E12: =J11/4 -> 2144912.2
C14: 3 | D14: BRITAMA (A/N MARJONO)
D15: JULI | E15: AGUSTUS | F15: SEPTEMBER | G15: OKTOBER
F16: 534737 | G16: 5540809 | J16: =F16+G16 -> 6075546
D17: =D12 -> RATA - RATA | E17: =J16/2 -> 3037773
C19: 4 | D19: BRITAMA (A/N TUNUT RIYADI)
D20: JULI | E20: AGUSTUS | F20: SEPTEMBER | G20: OKTOBER
F21: 125647284
C24: 5 | D24: BRITAMA (A/N JUMADI)
D25: JULI | E25: AGUSTUS | F25: SEPTEMBER | G25: OKTOBER
D26: 52122 | E26: 11530369 | F26: 66814 | G26: 11608859 | J26: =D26+E26+F26+G26 -> 23258164
D27: =D17 -> RATA - RATA | E27: =J26/4 -> 5814541
C29: 7 | D29: BRITAMA (A/N KRISTANTO)
D30: JULI | E30: AGUSTUS | F30: SEPTEMBER | G30: OKTOBER
F31: 68479370 | G31: 73531220 | J31: =F31+G31 -> 142010590
D32: =D27 -> RATA - RATA | E32: =J31/2 -> 71005295
D34: RATA - RATA KESELURUHAN | F34: =J34/6 -> 46101165 | J34: =E32+E27+E17+E12+E7+F21 -> 2.7660699e+08
D38: PENGUSUL | F38: INVESTIGATOR | H38: MENYETUJUI | J38: MENYETUJUI
D42: MARGO INANANG | F42: AGUS MJ | H42: YUFIANDY | J42: EKO NUGROHO, SE
D43: Account Officer | F43: Kasi Kredit | H43: Kadiv. Marketing | J43: Direktur
D45: MENYETUJUI | F45: MENYETUJUI | H45: MENYETUJUI
D49: TRI HIDAYAT, SE, Msi | F49: SYAMSUDIN | H49: Drs. EKO SUTRISNO W, MM
D50: Direktur Utama | F50: Dewan Pengawas | H50: Dewan Pengawas

Sheet CDD SDHRN
A1: PD. BPR BANK WONOSOBO
A3: FORMULIR CDD SEDERHANA
B4: Pengkinian data | F4: Walk in Customer | I4: Lainnya…………………………………..
A6: DATA PRIBADI/ PERORANGAN
A9: C.I.F | D9: :
A10: NAMA LENGKAP | D10: : | E10: ='DATA AWAL NASABAH'!B2 -> DYAH RETNO SULISTYOWATI
A11: NAMA ALIAS | D11: : | E11: ='DATA AWAL NASABAH'!B2 -> DYAH RETNO SULISTYOWATI
A12: JENIS KELAMIN | D12: : | F12: Laki Laki | I12: Perempuan
A13: Tempat, tanggal lahir | D13: : | E13: ='DATA AWAL NASABAH'!B3 -> WONOSOBO, 19-04-1978
A14: Nama Gadis Ibu Kandung | D14: : | E14: ='DATA AWAL NASABAH'!B22 -> SRI MURTINI
A15: Status | D15: : | F15: Menikah | H15: Belum menikah | J15: Janda/ Duda
A16: Jenis Identitas Diri | D16: : | F16: KTP | H16: Kartu Pelajar | J16: Paspor
F17: Lainnya…………
A18: Nomor Identitas | D18: : | E18: ='DATA AWAL NASABAH'!B16 -> 3307095904780003
A19: Nomor handphone | D19: : | E19: ='DATA AWAL NASABAH'!B15 -> 0811261088
A20: Alamat Sesuai Identitas | D20: : | E20: ='DATA AWAL NASABAH'!B12 -> JARAKSARI
A21: Kota | D21: : | E21: ='DATA AWAL NASABAH'!B14 -> WONOSOBO
A22: Alamat Tempat Tinggal Saat ini | D22: : | E22: =E20 -> JARAKSARI
A23: Kota | D23: : | E23: =E21 -> WONOSOBO
A24: Nomor Telepon Rumah | D24: :
A25: Status Rumah saat ini | D25: : | F25: Sendiri | H25: Orang tua | J25: Dinas
F26: Lainnya………..
A27: Pekerjaan | D27: : | E27: ='DATA AWAL NASABAH'!B4 -> PNS
A28: PERNYATAAN
G36: Wonosobo, ...............................................
G37: Mengetahui
A41: ='DATA AWAL NASABAH'!B2 -> DYAH RETNO SULISTYOWATI | D41: ='DATA AWAL NASABAH'!B30 -> ADRIAN WAHYU P | G41: YUFIANDY | J41: NANI TRI ASTUTI, SE
A42: Penyetor/ Nasabah | D42: Petugas | G42: APU & PPT | J42: Direksi

Sheet Sheet3
E12: 225000000
E13: 0.014
E14: =E12*E13 -> 3150000
